<?xml version="1.0" ?>
<sdf version='1.9'>
  <world name='default'>
    <physics name="1ms" type="ignore">
      <max_step_size>0.001</max_step_size>
      <real_time_factor>1.0</real_time_factor>
    </physics>

    <plugin filename="gz-sim-physics-system"
      name="gz::sim::systems::Physics">
    </plugin>
    <plugin
      filename="gz-sim-sensors-system"
      name="gz::sim::systems::Sensors">
      <render_engine>ogre2</render_engine>
    </plugin>
    <plugin filename="gz-sim-user-commands-system"
      name="gz::sim::systems::UserCommands">
    </plugin>
    <plugin filename="gz-sim-scene-broadcaster-system"
      name="gz::sim::systems::SceneBroadcaster">
    </plugin>
    <plugin filename="gz-sim-air-pressure-system"
      name="gz::sim::systems::AirPressure">
    </plugin>
    <plugin filename="gz-sim-air-speed-system"
      name="gz::sim::systems::AirSpeed">
    </plugin>
    <plugin filename="gz-sim-altimeter-system"
      name="gz::sim::systems::Altimeter">
    </plugin>
    <plugin filename="gz-sim-imu-system"
      name="gz::sim::systems::Imu">
    </plugin>
    <plugin filename="gz-sim-magnetometer-system"
      name="gz::sim::systems::Magnetometer">
    </plugin>
    <plugin filename="gz-sim-navsat-system"
      name="gz::sim::systems::NavSat">
    </plugin>

    <scene>
      <ambient>0.4 0.4 0.4 1</ambient>
      <background>0.7 0.7 0.7 1</background>
      <shadows>1</shadows>
      <sky></sky>
    </scene>

    <light name='sun' type='directional'>
      <cast_shadows>1</cast_shadows>
      <pose>0 0 10 0 -0 0</pose>
      <diffuse>0.8 0.8 0.8 1</diffuse>
      <specular>0.1 0.1 0.1 1</specular>
      <attenuation>
        <range>1000</range>
        <constant>0.9</constant>
        <linear>0.01</linear>
        <quadratic>0.001</quadratic>
      </attenuation>
      <direction>-0.5 0.5 -1</direction>
    </light>

    <model name='ground_plane'>
      <static>1</static>
      <link name='link'>
        <collision name='collision'>
          <geometry>
            <plane>
              <normal>0 0 1</normal>
              <size>100 100</size>
            </plane>
          </geometry>
          <surface>
            <friction>
              <ode>
                <mu>100</mu>
                <mu2>50</mu2>
              </ode>
            </friction>
          </surface>
        </collision>
        <visual name='visual'>
          <cast_shadows>0</cast_shadows>
          <geometry>
            <plane>
              <normal>0 0 1</normal>
              <size>100 100</size>
            </plane>
          </geometry>
          <material>
            <script>
              <uri>file://media/materials/scripts/gazebo.material</uri>
              <name>Gazebo/Grey</name>
            </script>
          </material>
        </visual>
      </link>
    </model>

    <model name='mud_box'>
      <static>1</static>
      <link name='link'>
        <collision name='collision'>
          <geometry><box><size>8 10 0.2</size></box></geometry>
        </collision>
        <visual name='visual_1'>
          <pose>-2 2.5 0 0 0 0</pose>
          <geometry><box><size>4 5 0.2</size></box></geometry>
          <material>
            <script>
              <uri>model://mud_box/materials/scripts</uri>
              <uri>model://mud_box/materials/textures</uri>
              <name>vrc/mud</name>
            </script>
          </material>
        </visual>
        <visual name='visual_2'><pose>2 2.5 0 0 0 0</pose><geometry><box><size>4 5 0.2</size></box></geometry><material><script><uri>model://mud_box/materials/scripts</uri><uri>model://mud_box/materials/textures</uri><name>vrc/mud</name></script></material></visual>
        <visual name='visual_3'><pose>2 -2.5 0 0 0 0</pose><geometry><box><size>4 5 0.2</size></box></geometry><material><script><uri>model://mud_box/materials/scripts</uri><uri>model://mud_box/materials/textures</uri><name>vrc/mud</name></script></material></visual>
        <visual name='visual_4'><pose>-2 -2.5 0 0 0 0</pose><geometry><box><size>4 5 0.2</size></box></geometry><material><script><uri>model://mud_box/materials/scripts</uri><uri>model://mud_box/materials/textures</uri><name>vrc/mud</name></script></material></visual>
      </link>
      <pose>-6.13192 4.89997 0 0 -0 0</pose>
    </model>
    
    <model name='mud_box_0'><static>1</static><link name='link'><collision name='collision'><geometry><box><size>8 10 0.2</size></box></geometry></collision><visual name='visual_1'><pose>-2 2.5 0 0 0 0</pose><geometry><box><size>4 5 0.2</size></box></geometry><material><script><uri>model://mud_box/materials/scripts</uri><uri>model://mud_box/materials/textures</uri><name>vrc/mud</name></script></material></visual></link><pose>1.90734 4.83104 0 0 -0 0</pose></model>
    <model name='mud_box_1'><static>1</static><link name='link'><collision name='collision'><geometry><box><size>8 10 0.2</size></box></geometry></collision><visual name='visual_1'><pose>-2 2.5 0 0 0 0</pose><geometry><box><size>4 5 0.2</size></box></geometry><material><script><uri>model://mud_box/materials/scripts</uri><uri>model://mud_box/materials/textures</uri><name>vrc/mud</name></script></material></visual></link><pose>-6.12792 -5.13998 0 0 -0 0</pose></model>
    <model name='mud_box_2'><static>1</static><link name='link'><collision name='collision'><geometry><box><size>8 10 0.2</size></box></geometry></collision><visual name='visual_1'><pose>-2 2.5 0 0 0 0</pose><geometry><box><size>4 5 0.2</size></box></geometry><material><script><uri>model://mud_box/materials/scripts</uri><uri>model://mud_box/materials/textures</uri><name>vrc/mud</name></script></material></visual></link><pose>1.85975 -5.14192 0 0 -0 0</pose></model>

    <model name='oak_tree'>
      <static>1</static>
      <link name='link'>
        <collision name='collision'>
          <geometry><mesh><uri>model://oak_tree/meshes/oak_tree.dae</uri><scale>1 1 1</scale></mesh></geometry>
        </collision>
        <visual name='branch'>
          <geometry><mesh><uri>model://oak_tree/meshes/oak_tree.dae</uri><submesh><name>Branch</name></submesh><scale>1 1 1</scale></mesh></geometry>
          <material><script><uri>model://oak_tree/materials/scripts/</uri><uri>model://oak_tree/materials/textures/</uri><name>OakTree/Branch</name></script></material>
        </visual>
        <visual name='bark'>
          <geometry><mesh><uri>model://oak_tree/meshes/oak_tree.dae</uri><submesh><name>Bark</name></submesh><scale>1 1 1</scale></mesh></geometry>
          <material><script><uri>model://oak_tree/materials/scripts/</uri><uri>model://oak_tree/materials/textures/</uri><name>OakTree/Bark</name></script></material>
        </visual>
      </link>
      <pose>18.6162 -7.97862 0 0 -0 0</pose>
    </model>
    
    <model name="realistic_fire">
      <pose>5 0 0.1 0 0 0</pose>
      <static>true</static>
      <link name="fire_core">
        <visual name="core">
          <geometry>
            <cylinder><radius>0.8</radius><length>1.5</length></cylinder>
          </geometry>
          <material>
            <ambient>1.0 0.2 0.0 1</ambient>
            <diffuse>1.0 0.2 0.0 1</diffuse>
           <emissive>1.0 0.5 0.0 1</emissive>
          </material>
        </visual>
      </link>
      <link name="fire_flicker">
        <pose>0 0 0.5 0 0 0</pose>
        <visual name="flicker">
          <geometry><sphere><radius>0.4</radius></sphere></geometry>
          <material>
            <ambient>1.0 0.4 0.1 1</ambient>
            <diffuse>1.0 0.4 0.1 1</diffuse>
            <emissive>1.0 0.5 0.0 1</emissive>
          </material>
        </visual>
      </link>
    </model>

    <light name="fire_light" type="point">
      <pose>5 0 2 0 0 0</pose> <diffuse>1.0 0.6 0.1 1</diffuse>
      <specular>0.3 0.3 0.3 1</specular>
      <attenuation>
        <range>25</range>
        <constant>0.3</constant>
        <linear>0.01</linear>
        <quadratic>0.02</quadratic>
      </attenuation>
    </light>

    <model name="iris">
      <pose degrees="true">0 0 0.195 0 0 90</pose>
      <link name='base_link'>
        <inertial>
          <pose>0 0 0 0 0 0</pose>
          <mass>1.5</mass>
          <inertia>
            <ixx>0.008</ixx><ixy>0</ixy><ixz>0</ixz>
            <iyy>0.015</iyy><iyz>0</iyz><izz>0.017</izz>
          </inertia>
        </inertial>
        <collision name='base_collision'>
          <pose>0 0 -0.08 0 0 0</pose>
          <geometry><box><size>0.47 0.47 0.23</size></box></geometry>
          <surface>
            <contact>
              <ode><max_vel>100.0</max_vel><min_depth>0.001</min_depth></ode>
            </contact>
            <friction>
              <ode><mu>100000.0</mu><mu2>100000.0</mu2></ode>
            </friction>
          </surface>
        </collision>
        <visual name='base_visual'>
          <geometry><mesh><uri>model://iris_with_standoffs/meshes/iris.dae</uri></mesh></geometry>
          <material>
            <ambient>0.05 0.05 0.05</ambient><diffuse>0.05 0.05 0.05</diffuse><specular>1 1 1 1</specular>
          </material>
        </visual>
        
        <visual name='front_left_leg_visual'>
          <pose>0.123 0.22 -0.11 0 0 0</pose>
          <geometry><cylinder><radius>0.005</radius><length>0.17</length></cylinder></geometry>
          <material><ambient>0.05 0.05 0.05</ambient><diffuse>0.05 0.05 0.05</diffuse></material>
        </visual>
        <visual name='front_right_leg_visual'>
          <pose>0.123 -0.22 -0.11 0 0 0</pose>
          <geometry><cylinder><radius>0.005</radius><length>0.17</length></cylinder></geometry>
          <material><ambient>0.05 0.05 0.05</ambient><diffuse>0.05 0.05 0.05</diffuse></material>
        </visual>
        <visual name='rear_left_leg_visual'>
          <pose>-0.140 0.21 -0.11 0 0 0</pose>
          <geometry><cylinder><radius>0.005</radius><length>0.17</length></cylinder></geometry>
          <material><ambient>0.05 0.05 0.05</ambient><diffuse>0.05 0.05 0.05</diffuse></material>
        </visual>
        <visual name='rear_right_leg_visual'>
          <pose>-0.140 -0.21 -0.11 0 0 0</pose>
          <geometry><cylinder><radius>0.005</radius><length>0.17</length></cylinder></geometry>
          <material><ambient>0.05 0.05 0.05</ambient><diffuse>0.05 0.05 0.05</diffuse></material>
        </visual>

        <sensor name="air_pressure_sensor" type="air_pressure"><always_on>1</always_on><update_rate>30</update_rate></sensor>
        <sensor name="air_speed_sensor" type="air_speed"><always_on>1</always_on><update_rate>30</update_rate></sensor>
        <sensor name="altimeter_sensor" type="altimeter"><always_on>1</always_on><update_rate>30</update_rate></sensor>
        <sensor name="magnetometer_sensor" type="magnetometer"><always_on>1</always_on><update_rate>30</update_rate></sensor>
        <sensor name="navsat_sensor" type="navsat"><always_on>1</always_on><update_rate>30</update_rate></sensor>
      </link>

      <link name='imu_link'>
        <inertial>
          <mass>0.15</mass>
          <inertia><ixx>0.00001</ixx><ixy>0</ixy><ixz>0</ixz><iyy>0.00002</iyy><iyz>0</iyz><izz>0.00002</izz></inertia>
        </inertial>
        <sensor name="imu_sensor" type="imu">
          <pose degrees="true">0 0 0 180 0 0</pose>
          <always_on>1</always_on>
          <update_rate>1000.0</update_rate>
        </sensor>
      </link>
      <joint name='imu_joint' type='revolute'>
        <child>imu_link</child><parent>base_link</parent>
        <axis><xyz>0 0 1</xyz><limit><lower>0</lower><upper>0</upper></limit></axis>
      </joint>

      <link name='rotor_0'>
        <pose>0.13 -0.22 0.023 0 0 0</pose>
        <inertial><mass>0.025</mass><inertia><ixx>9.75e-06</ixx><ixy>0</ixy><ixz>0</ixz><iyy>0.000166704</iyy><iyz>0</iyz><izz>0.000167604</izz></inertia></inertial>
        <visual name='rotor_0_visual'><geometry><mesh><scale>1 1 1</scale><uri>model://iris_with_standoffs/meshes/iris_prop_ccw.dae</uri></mesh></geometry></visual>
      </link>
      <joint name='rotor_0_joint' type='revolute'>
        <child>rotor_0</child><parent>base_link</parent>
        <axis><xyz>0 0 1</xyz><dynamics><damping>0.004</damping></dynamics></axis>
      </joint>

      <link name='rotor_1'>
        <pose>-0.13 0.2 0.023 0 0 0</pose>
        <inertial><mass>0.025</mass><inertia><ixx>9.75e-06</ixx><ixy>0</ixy><ixz>0</ixz><iyy>0.000166704</iyy><iyz>0</iyz><izz>0.000167604</izz></inertia></inertial>
        <visual name='rotor_1_visual'><geometry><mesh><scale>1 1 1</scale><uri>model://iris_with_standoffs/meshes/iris_prop_ccw.dae</uri></mesh></geometry></visual>
      </link>
      <joint name='rotor_1_joint' type='revolute'>
        <child>rotor_1</child><parent>base_link</parent>
        <axis><xyz>0 0 1</xyz><dynamics><damping>0.004</damping></dynamics></axis>
      </joint>

      <link name='rotor_2'>
        <pose>0.13 0.22 0.023 0 0 0</pose>
        <inertial><mass>0.025</mass><inertia><ixx>9.75e-06</ixx><ixy>0</ixy><ixz>0</ixz><iyy>0.000166704</iyy><iyz>0</iyz><izz>0.000167604</izz></inertia></inertial>
        <visual name='rotor_2_visual'><geometry><mesh><scale>1 1 1</scale><uri>model://iris_with_standoffs/meshes/iris_prop_cw.dae</uri></mesh></geometry></visual>
      </link>
      <joint name='rotor_2_joint' type='revolute'>
        <child>rotor_2</child><parent>base_link</parent>
        <axis><xyz>0 0 1</xyz><dynamics><damping>0.004</damping></dynamics></axis>
      </joint>

      <link name='rotor_3'>
        <pose>-0.13 -0.2 0.023 0 0 0</pose>
        <inertial><mass>0.025</mass><inertia><ixx>9.75e-06</ixx><ixy>0</ixy><ixz>0</ixz><iyy>0.000166704</iyy><iyz>0</iyz><izz>0.000167604</izz></inertia></inertial>
        <visual name='rotor_3_visual'><geometry><mesh><scale>1 1 1</scale><uri>model://iris_with_standoffs/meshes/iris_prop_cw.dae</uri></mesh></geometry></visual>
      </link>
      <joint name='rotor_3_joint' type='revolute'>
        <child>rotor_3</child><parent>base_link</parent>
        <axis><xyz>0 0 1</xyz><dynamics><damping>0.004</damping></dynamics></axis>
      </joint>

      <plugin filename="gz-sim-joint-state-publisher-system" name="gz::sim::systems::JointStatePublisher"></plugin>
      <plugin filename="gz-sim-odometry-publisher-system" name="gz::sim::systems::OdometryPublisher">
        <odom_frame>odom</odom_frame>
        <robot_base_frame>base_link</robot_base_frame>
        <dimensions>3</dimensions>
      </plugin>
      
      <plugin filename="gz-sim-lift-drag-system" name="gz::sim::systems::LiftDrag">
        <a0>0.3</a0><cla>4.25</cla><cda>0.10</cda><area>0.002</area><air_density>1.2041</air_density>
        <cp>0.084 0 0</cp><forward>0 1 0</forward><upward>0 0 1</upward><link_name>rotor_0</link_name>
      </plugin>
      <plugin filename="gz-sim-lift-drag-system" name="gz::sim::systems::LiftDrag">
        <a0>0.3</a0><cla>4.25</cla><cda>0.10</cda><area>0.002</area><air_density>1.2041</air_density>
        <cp>-0.084 0 0</cp><forward>0 -1 0</forward><upward>0 0 1</upward><link_name>rotor_0</link_name>
      </plugin>
      
      <plugin filename="gz-sim-lift-drag-system" name="gz::sim::systems::LiftDrag">
        <a0>0.3</a0><cla>4.25</cla><cda>0.10</cda><area>0.002</area><air_density>1.2041</air_density>
        <cp>0.084 0 0</cp><forward>0 1 0</forward><upward>0 0 1</upward><link_name>rotor_1</link_name>
      </plugin>
      <plugin filename="gz-sim-lift-drag-system" name="gz::sim::systems::LiftDrag">
        <a0>0.3</a0><cla>4.25</cla><cda>0.10</cda><area>0.002</area><air_density>1.2041</air_density>
        <cp>-0.084 0 0</cp><forward>0 -1 0</forward><upward>0 0 1</upward><link_name>rotor_1</link_name>
      </plugin>

      <plugin filename="gz-sim-lift-drag-system" name="gz::sim::systems::LiftDrag">
        <a0>0.3</a0><cla>4.25</cla><cda>0.10</cda><area>0.002</area><air_density>1.2041</air_density>
        <cp>0.084 0 0</cp><forward>0 -1 0</forward><upward>0 0 1</upward><link_name>rotor_2</link_name>
      </plugin>
      <plugin filename="gz-sim-lift-drag-system" name="gz::sim::systems::LiftDrag">
        <a0>0.3</a0><cla>4.25</cla><cda>0.10</cda><area>0.002</area><air_density>1.2041</air_density>
        <cp>-0.084 0 0</cp><forward>0 1 0</forward><upward>0 0 1</upward><link_name>rotor_2</link_name>
      </plugin>

      <plugin filename="gz-sim-lift-drag-system" name="gz::sim::systems::LiftDrag">
        <a0>0.3</a0><cla>4.25</cla><cda>0.10</cda><area>0.002</area><air_density>1.2041</air_density>
        <cp>0.084 0 0</cp><forward>0 -1 0</forward><upward>0 0 1</upward><link_name>rotor_3</link_name>
      </plugin>
      <plugin filename="gz-sim-lift-drag-system" name="gz::sim::systems::LiftDrag">
        <a0>0.3</a0><cla>4.25</cla><cda>0.10</cda><area>0.002</area><air_density>1.2041</air_density>
        <cp>-0.084 0 0</cp><forward>0 1 0</forward><upward>0 0 1</upward><link_name>rotor_3</link_name>
      </plugin>

      <plugin filename="gz-sim-apply-joint-force-system" name="gz::sim::systems::ApplyJointForce"><joint_name>rotor_0_joint</joint_name></plugin>
      <plugin filename="gz-sim-apply-joint-force-system" name="gz::sim::systems::ApplyJointForce"><joint_name>rotor_1_joint</joint_name></plugin>
      <plugin filename="gz-sim-apply-joint-force-system" name="gz::sim::systems::ApplyJointForce"><joint_name>rotor_2_joint</joint_name></plugin>
      <plugin filename="gz-sim-apply-joint-force-system" name="gz::sim::systems::ApplyJointForce"><joint_name>rotor_3_joint</joint_name></plugin>

      <plugin filename="gz-sim-linearbatteryplugin-system" name="gz::sim::systems::LinearBatteryPlugin">
        <battery_name>lipo_3500mAh</battery_name>
        <fix_issue_225>true</fix_issue_225>
        <open_circuit_voltage_constant_coef>12.6</open_circuit_voltage_constant_coef>
        <open_circuit_voltage_linear_coef>-2.7</open_circuit_voltage_linear_coef>
        <capacity>3.5</capacity>
        <voltage>12.6</voltage>
        <initial_charge>3.5</initial_charge>
        <power_load>200.0</power_load>
        <start_draining>false</start_draining>
      </plugin>

      <plugin name="ArduPilotPlugin" filename="ArduPilotPlugin">
        <fdm_addr>127.0.0.1</fdm_addr>
        <fdm_port_in>9002</fdm_port_in>
        <connectionTimeoutMaxCount>5</connectionTimeoutMaxCount>
        <lock_step>1</lock_step>
        <modelXYZToAirplaneXForwardZDown degrees="true">0 0 0 180 0 0</modelXYZToAirplaneXForwardZDown>
        <gazeboXYZToNED degrees="true">0 0 0 180 0 90</gazeboXYZToNED>
        <imuName>imu_link::imu_sensor</imuName>
        <control channel="0">
          <jointName>rotor_0_joint</jointName><useForce>1</useForce><multiplier>838</multiplier><offset>0</offset>
          <servo_min>1100</servo_min><servo_max>1900</servo_max><type>VELOCITY</type>
          <p_gain>0.20</p_gain><i_gain>0</i_gain><d_gain>0</d_gain><i_max>0</i_max><i_min>0</i_min>
          <cmd_max>2.5</cmd_max><cmd_min>-2.5</cmd_min><controlVelocitySlowdownSim>1</controlVelocitySlowdownSim>
        </control>
        <control channel="1">
          <jointName>rotor_1_joint</jointName><useForce>1</useForce><multiplier>838</multiplier><offset>0</offset>
          <servo_min>1100</servo_min><servo_max>1900</servo_max><type>VELOCITY</type>
          <p_gain>0.20</p_gain><i_gain>0</i_gain><d_gain>0</d_gain><i_max>0</i_max><i_min>0</i_min>
          <cmd_max>2.5</cmd_max><cmd_min>-2.5</cmd_min><controlVelocitySlowdownSim>1</controlVelocitySlowdownSim>
        </control>
        <control channel="2">
          <jointName>rotor_2_joint</jointName><useForce>1</useForce><multiplier>-838</multiplier><offset>0</offset>
          <servo_min>1100</servo_min><servo_max>1900</servo_max><type>VELOCITY</type>
          <p_gain>0.20</p_gain><i_gain>0</i_gain><d_gain>0</d_gain><i_max>0</i_max><i_min>0</i_min>
          <cmd_max>2.5</cmd_max><cmd_min>-2.5</cmd_min><controlVelocitySlowdownSim>1</controlVelocitySlowdownSim>
        </control>
        <control channel="3">
          <jointName>rotor_3_joint</jointName><useForce>1</useForce><multiplier>-838</multiplier><offset>0</offset>
          <servo_min>1100</servo_min><servo_max>1900</servo_max><type>VELOCITY</type>
          <p_gain>0.20</p_gain><i_gain>0</i_gain><d_gain>0</d_gain><i_max>0</i_max><i_min>0</i_min>
          <cmd_max>2.5</cmd_max><cmd_min>-2.5</cmd_min><controlVelocitySlowdownSim>1</controlVelocitySlowdownSim>
        </control>
      </plugin>

      <link name="depth_camera_link">
        <pose>0.25 0 0.08 0 0.612 0</pose>
        <inertial><mass>0.05</mass><inertia><ixx>1e-4</ixx><ixy>0</ixy><ixz>0</ixz><iyy>1e-4</iyy><iyz>0</iyz><izz>1e-4</izz></inertia></inertial>
        <sensor name="depth_camera" type="depth">
          <pose>0 0 0 0 0 0</pose><update_rate>30</update_rate><always_on>true</always_on>
          <camera>
            <horizontal_fov>1.047</horizontal_fov>
            <image><width>640</width><height>480</height><format>R8G8B8</format></image>
            <clip><near>0.1</near><far>20.0</far></clip>
          </camera>
          <visualize>true</visualize>
        </sensor>
        <sensor name="rgb_camera" type="camera">
          <pose>0 0 0 0 0 0</pose><update_rate>30</update_rate><always_on>true</always_on>
          <camera>
            <horizontal_fov>1.047</horizontal_fov>
            <image><width>640</width><height>480</height><format>R8G8B8</format></image>
            <clip><near>0.1</near><far>20.0</far></clip>
          </camera>
          <visualize>true</visualize>
        </sensor>
      </link>
      <joint name="depth_camera_joint" type="fixed">
        <parent>base_link</parent>
        <child>depth_camera_link</child>
      </joint>

    </model>
  </world>
</sdf>